Workbook

Sheet BenchmarkFacebookPageIDs.csv
A1: ='Barracuda Group'!B:B -> Facebook.com/ | B1: =McMullen!B:B -> Facebook.com/ | C1: =Stonegate!B:B -> Facebook.com/ | D1: ='Young''s'!B:B -> Facebook.com/ | E1: =Brakspear!B:B -> Facebook.com/ | F1: Facebook.com/
A2: ='Barracuda Group'!B:B -> partyatthepub | B2: =McMullen!B:B -> BarooshCambridge | C2: =Stonegate!B:B -> 241916805827554 | D2: ='Young''s'!B:B -> devonshirebalham | E2: =Brakspear!B:B -> TheAbingdonArms | F2: 338643409499578
A3: ='Barracuda Group'!B:B -> 117514205009904 | B3: =McMullen!B:B -> BarooshChelmsford | C3: =Stonegate!B:B -> 204970242889126 | D3: ='Young''s'!B:B -> 123916907641573 | E3: =Brakspear!B:B -> angel.onthebridge | F3: 153429008029137
A4: ='Barracuda Group'!B:B -> abacus.chesterfield | B4: =McMullen!B:B -> BarooshStaines | C4: =Stonegate!B:B -> TheBeehiveSheffield | D4: ='Young''s'!B:B -> whitehartbarnes | E4: =Brakspear!B:B -> 131664686913443 | F4: 238514489535568
A5: ='Barracuda Group'!B:B -> 111890268896874 | B5: =McMullen!B:B -> BarooshUxbridge | C5: =Stonegate!B:B -> liveatthebull | D5: ='Young''s'!B:B -> 46902290945 | E5: =Brakspear!B:B -> 125633597494393 | F5: 296520687025509
A6: ='Barracuda Group'!B:B -> 214007299724 | B6: =McMullen!B:B -> BarooshHerts | C6: =Stonegate!B:B -> thecrowncorporationstreet | D6: ='Young''s'!B:B -> 157688500925050 | E6: =Brakspear!B:B -> 100001346341852 | F6: 137053349730163
A7: ='Barracuda Group'!B:B -> abbeynuneaton | B7: =McMullen!B:B -> BarooshStortford | C7: =Stonegate!B:B -> TheDukeofSomersetInLondon | D7: ='Young''s'!B:B -> 0 | E7: =Brakspear!B:B -> Circus.Circus.Brighton | F7: 125769490781715
A8: ='Barracuda Group'!B:B -> academybar | B8: =McMullen!B:B -> Bullfinch7 | C8: =Stonegate!B:B -> 166226923446287 | D8: ='Young''s'!B:B -> 100000830414416 | E8: =Brakspear!B:B -> claytonsmarlow | F8: 214542908559038
A9: ='Barracuda Group'!B:B -> Academy.Preston | B9: =McMullen!B:B -> BullsHeadBrox | C9: =Stonegate!B:B -> thegeorgesouthwoodford | D9: ='Young''s'!B:B -> 100001193717573 | E9: =Brakspear!B:B -> 175321173254 | F9: 127542450625367
A10: ='Barracuda Group'!B:B -> 236612136402 | B10: =McMullen!B:B -> CampAlbans | C10: =Stonegate!B:B -> 118596071565880 | D10: ='Young''s'!B:B -> 100001166266542 | E10: =Brakspear!B:B -> 100334996706932 | F10: 106193507918
A11: ='Barracuda Group'!B:B -> Alchemist.Houndsditch | B11: =McMullen!B:B -> ChieftainWGC | C11: =Stonegate!B:B -> GranthamGoose | D11: ='Young''s'!B:B -> 108124085944121 | F11: 190201820919
A12: ='Barracuda Group'!B:B -> TheAlibiManchester | B12: =McMullen!B:B -> 171210472920864 | C12: =Stonegate!B:B -> 205316169518741 | D12: ='Young''s'!B:B -> 146650128683527 | F12: 167616527814
A13: ='Barracuda Group'!B:B -> 125528727526892 | B13: =McMullen!B:B -> CockONorthBell | C13: =Stonegate!B:B -> 125608250841977 | D13: ='Young''s'!B:B -> TheLambTavern | F13: 160807040621151
A14: ='Barracuda Group'!B:B -> 154070864610764 | B14: =McMullen!B:B -> CricketersEnfield | C14: =Stonegate!B:B -> gooseromford | D14: ='Young''s'!B:B -> WindmillClapham | F14: 36032334017
A15: ='Barracuda Group'!B:B -> 212475182159213 | B15: =McMullen!B:B -> crocodilecheshunt | C15: =Stonegate!B:B -> TheOVT | D15: ='Young''s'!B:B -> grangeealing | F15: 117619418282181
A16: ='Barracuda Group'!B:B -> 244165755594378 | B16: =McMullen!B:B -> CrusaderRoydon | C16: =Stonegate!B:B -> TheGosforthHotel | D16: ='Young''s'!B:B -> 100001244385500 | F16: 105673019493970
A17: ='Barracuda Group'!B:B -> 105958794224 | B17: =McMullen!B:B -> TheDuchessPub | C17: =Stonegate!B:B -> 189899484382787 | D17: ='Young''s'!B:B -> 110899878978738 | F17: 91086933945
A18: ='Barracuda Group'!B:B -> thebarbican.scarborough | B18: =McMullen!B:B -> FisheryElstree | C18: =Stonegate!B:B -> 331119655629 | D18: ='Young''s'!B:B -> onetungoodge | F18: 146650128683527
A19: ='Barracuda Group'!B:B -> barracuda.hull | B19: =McMullen!B:B -> GoldenGriffinHerts | C19: =Stonegate!B:B -> themanchesterblackpool | D19: ='Young''s'!B:B -> 129057682349 | F19: 153111468060034
A20: ='Barracuda Group'!B:B -> barracuda.bar.boro | B20: =McMullen!B:B -> GreyhoundEnfield | C20: =Stonegate!B:B -> 281716254458 | D20: ='Young''s'!B:B -> 100002674768646 | F20: 129057682349
A21: ='Barracuda Group'!B:B -> Thebeacon.Wellington | B21: =McMullen!B:B -> HareHarlow | C21: =Stonegate!B:B -> TheOldGeorgeInn | D21: ='Young''s'!B:B -> 152933738060457 | F21: 130548070289696
A22: ='Barracuda Group'!B:B -> 151797531533672 | B22: =McMullen!B:B -> HarrierHatfield | C22: =Stonegate!B:B -> 118426311584560 | D22: ='Young''s'!B:B -> 758492012 | F22: 152933738060457
... A41: ='Barracuda Group'!B:B -> 101646685842 | B41: =McMullen!B:B -> OldRedLion | C41: =Stonegate!B:B -> Osbert.Oink | D41: ='Young''s'!B:B -> RichardtheFirstGreenwich | F41: 147576498642150
A42: ='Barracuda Group'!B:B -> 223756747666102 | C42: =Stonegate!B:B -> 193064350737987 | D42: ='Young''s'!B:B -> FApub | F42: 203767962988110
D43: ='Young''s'!B:B -> 1395866936 | F43: 195224167181026
D44: ='Young''s'!B:B -> 214542908559038 | F44: 208516652493890
D45: ='Young''s'!B:B -> 150373421667187 | F45: 111281772284362
D46: ='Young''s'!B:B -> 118657678165411 | F46: 195758310457088
D47: ='Young''s'!B:B -> 131029546975670 | F47: 199124706774704
D48: ='Young''s'!B:B -> 325678384870 | F48: 154327617960451
D49: ='Young''s'!B:B -> plough.beddington | F49: 112937728785380
D50: ='Young''s'!B:B -> 100001250300990 | F50: 166417406751109
D51: ='Young''s'!B:B -> 130230740326648 | F51: 106010476153625
D52: ='Young''s'!B:B -> 109164705809625 | F52: 125428480870471
F53: 145212355552718
F54: 213679651975867
F55: 203705039650570
F56: 217724431578065
F57: 117461938339151
F58: 107252469371385
...

Sheet Barracuda Group
A1: Format | B1: Facebook.com/ | C1: Likes | D1: Friends
A2: Page | B2: partyatthepub | C2: 3586
A3: Page | B3: 117514205009904 | C3: 302
A4: Personal | B4: abacus.chesterfield | D4: 4929
A5: Page | B5: 111890268896874 | C5: 27
A6: Page | B6: 214007299724 | C6: 752
A7: Page | B7: abbeynuneaton | C7: 226
A8: Personal | B8: academybar | D8: 3328
A9: Page | B9: Academy.Preston | C9: 2262
A10: Page | B10: 236612136402 | C10: 522
A11: Page | B11: Alchemist.Houndsditch | C11: 145
A12: Page | B12: TheAlibiManchester | C12: 680
A13: Page | B13: 125528727526892 | C13: 262
A14: Page | B14: 154070864610764 | C14: 591
A15: Page | B15: 212475182159213 | C15: 2
A16: Page | B16: 244165755594378 | C16: 45
A17: Page | B17: 105958794224 | C17: 254
A18: Page | B18: thebarbican.scarborough | C18: 595
A19: Page | B19: barracuda.hull | C19: 4710
A20: Page | B20: barracuda.bar.boro | C20: 1325
A21: Personal | B21: Thebeacon.Wellington | D21: 1415
A22: Page | B22: 151797531533672 | C22: 131
A23: Page | B23: 54569614369 | C23: 907
A24: Page | B24: bluebell.middlesbrough | C24: 324
A25: Page | B25: 158759350831538 | C25: 174
A26: Page | B26: 62011504510 | C26: 2124
A27: Page | B27: the.bridgewater | C27: 4977
A28: Page | B28: brunel.chippenham | C28: 2348
A29: Page | B29: 63021005821 | C29: 1587
A30: Personal | B30: 100001090340271 | D30: 3134
A31: Page | B31: 152413508145227 | C31: 508
A32: Page | B32: 62632989396 | C32: 300
A33: Personal | B33: cambusbar | D33: 224
A34: Personal | B34: canutes.gainsborough | D34: 1267
A35: Page | B35: CapeBar.Woodstreet | C35: 223
A36: Page | B36: 192314220791481 | C36: 97
A37: Page | B37: 194144697277285 | C37: 112
A38: Page | B38: 47278996839 | C38: 1268
A39: Page | B39: capebar | C39: 139
A40: Page | B40: 174141609267304 | C40: 234
...

Sheet McMullen
A1: Format | B1: Facebook.com/ | C1: Likes
A2: Page | B2: BarooshCambridge | C2: 57
A3: Page | B3: BarooshChelmsford | C3: 362
A4: Page | B4: BarooshStaines | C4: 214
A5: Page | B5: BarooshUxbridge | C5: 141
A6: Page | B6: BarooshHerts | C6: 331
A7: Page | B7: BarooshStortford | C7: 187
A8: Page | B8: Bullfinch7 | C8: 172
A9: Page | B9: BullsHeadBrox | C9: 390
A10: Page | B10: CampAlbans | C10: 96
A11: Page | B11: ChieftainWGC | C11: 495
A12: Page | B12: 171210472920864 | C12: 47
A13: Page | B13: CockONorthBell | C13: 213
A14: Page | B14: CricketersEnfield | C14: 77
A15: Page | B15: crocodilecheshunt | C15: 340
A16: Page | B16: CrusaderRoydon | C16: 53
A17: Page | B17: TheDuchessPub | C17: 117
A18: Page | B18: FisheryElstree | C18: 289
A19: Page | B19: GoldenGriffinHerts | C19: 83
A20: Page | B20: GreyhoundEnfield | C20: 124
A21: Page | B21: HareHarlow | C21: 377
A22: Page | B22: HarrierHatfield | C22: 231
A23: Page | B23: HeraldHarlow | C23: 31
A24: Page | B24: HeronLakeFleet | C24: 294
... A26: Page | B26: HopfieldsHat | C26: 223
A27: Page | B27: 121580111209151 | C27: 27
A28: Page | B28: JollyButchers | C28: 122
A29: Page | B29: JollyEnfield | C29: 103
A30: Page | B30: JollyFishWare | C30: 169
A31: Page | B31: 117226721621921 | C31: 10
A32: Page | B32: LordKitBarnet | C32: 264
A33: Page | B33: MaltstersCheshunt | C33: 64
A34: Page | B34: MillsHitchin | C34: 197
A35: Page | B35: MopsBrooms | C35: 241
A36: Page | B36: NagsHeadLondon | C36: 247
A37: Page | B37: NagsHeadBS | C37: 376
A38: Page | B38: NorthStarWelwyn | C38: 140
A39: Page | B39: OldAnchorCheshunt | C39: 34
A40: Page | B40: OldBeamsMK | C40: 514
A41: Page | B41: OldRedLion | C41: 41

Sheet Stonegate
A1: Format | B1: Facebook.com/ | C1: Likes | D1: Friends/Members
A2: Page | B2: 241916805827554 | C2: 126
A3: Page | B3: 204970242889126 | C3: 2
A4: Page | B4: TheBeehiveSheffield | C4: 144
A5: Page | B5: liveatthebull | C5: 96
A6: Page | B6: thecrowncorporationstreet | C6: 57
A7: Page | B7: TheDukeofSomersetInLondon | C7: 43
A8: Page | B8: 166226923446287 | C8: 27
A9: Page | B9: thegeorgesouthwoodford | C9: 241
A10: Page | B10: 118596071565880 | C10: 145
A11: Page | B11: GranthamGoose
A12: Page | B12: 205316169518741 | C12: 30
A13: Page | B13: 125608250841977 | C13: 39
A14: Page | B14: gooseromford | C14: 554
A15: Page | B15: TheOVT | C15: 187
A16: Page | B16: TheGosforthHotel | C16: 371
A17: Page | B17: 189899484382787 | C17: 172
A18: Page | B18: 331119655629 | C18: 143
A19: Page | B19: themanchesterblackpool | C19: 385
A20: Page | B20: 281716254458 | C20: 299
A21: Page | B21: TheOldGeorgeInn | C21: 295
A22: Page | B22: 118426311584560 | C22: 6
A23: Page | B23: 251817034832451 | C23: 52
A24: Page | B24: 122158654540655 | C24: 123
A25: Page | B25: LadyWulfrun | C25: 224
A26: Page | B26: TownCrierPub.Chester | C26: 155
A27: Page | B27: 178072088902444 | C27: 47
A28: Page | B28: bedfordsbar | C28: 124
A29: Personal | B29: 100001602065159 | D29: 1386
A30: Page | B30: 196848213694254 | C30: 2
A31: Personal | B31: fiddler.cleethorpes | D31: 682
A32: Personal | B32: 100002185706166 | D32: 174
A33: Page | B33: 11570179293 | C33: 297
A34: Personal | B34: hogshead.cheltenham | D34: 1364
A35: Page | B35: 259613480720446 | C35: 5
A36: Page | B36: 132195856802215 | C36: 77
A37: Personal | B37: hogshead.hornchurch | D37: 242
A38: Personal | B38: 1530241508 | D38: 2184
A39: Personal | B39: 100002364372755 | D39: 13
A40: Personal | B40: 1249603989 | D40: 200
...

Sheet Young's
A1: Format | B1: Facebook.com/ | C1: Likes | D1: Friends/Members
A2: Page | B2: devonshirebalham | C2: 100
A3: Page | B3: 123916907641573 | C3: 82
A4: Page | B4: whitehartbarnes | C4: 27
A5: Page | B5: 46902290945 | C5: 181
A6: Page | B6: 157688500925050 | C6: 165
A7: Page | C7: 214
A8: Personal | B8: 100000830414416 | D8: 276
A9: Personal | B9: 100001193717573 | D9: 274
A10: Personal | B10: 100001166266542 | D10: 271
A11: Page | B11: 108124085944121 | C11: 31
A12: Page | B12: 146650128683527 | C12: 653
A13: Personal | B13: TheLambTavern | D13: 98
A14: Page | B14: WindmillClapham | C14: 518
A15: Page | B15: grangeealing | C15: 35
A16: Personal | B16: 100001244385500 | D16: 126
A17: Page | B17: 110899878978738 | C17: 55
A18: Page | B18: onetungoodge | C18: 66
A19: Page | B19: 129057682349 | C19: 57
A20: Personal | B20: 100002674768646 | D20: 344
A21: Page | B21: 152933738060457 | C21: 66
A22: Personal | B22: 758492012 | D22: 1471
A23: Page | B23: oldshipw6 | C23: 229
A24: Page | B24: 224971467518584 | C24: 31
A25: Page | B25: 200123943356438 | C25: 24
A26: Page | B26: beaufortpubdining | C26: 71
A27: Page | B27: 150098788348346 | C27: 88
A28: Page | B28: 160516460629954 | C28: 22
A29: Page | B29: 103494476395774 | C29: 69
A30: Page | B30: 179781635398178 | C30: 69
A31: Page | B31: GuineaGrill | C31: 118
A32: Page | B32: tweetiepieW1 | C32: 81
A33: Personal | B33: porchester | D33: 106
A34: Page | B34: 166805230045250 | C34: 21
A35: Page | B35: 126501290703182 | C35: 31
A36: Page | B36: 274883719044 | C36: 283
A37: Page | B37: 148258805242405 | C37: 147
A38: Page | B38: 127542450625367 | C38: 129
A39: Personal | B39: clockhouse | D39: 164
A40: Personal | B40: 100001044721641 | D40: 0
...

Sheet Brakspear
A1: Format | B1: Facebook.com/ | C1: Likes | D1: Friends/Members
A2: Page | B2: TheAbingdonArms | C2: 45
A3: Personal | B3: angel.onthebridge | D3: 545
A4: Page | B4: 131664686913443 | C4: 8
A5: Page | B5: 125633597494393 | C5: 78
A6: Personal | B6: 100001346341852 | D6: 51
A7: Page | B7: Circus.Circus.Brighton | C7: 787
A8: Personal | B8: claytonsmarlow | D8: 433
A9: Page | B9: 175321173254 | C9: 458
A10: Page | B10: 100334996706932 | C10: 112
